18-05-2020 09:31:26 DEBUG tests.test_acceptance.acceptance_base_class (test_check_column_constraints) Certificate column constraints... 
18-05-2020 09:31:26 DEBUG tests.test_acceptance.acceptance_base_class (test_check_column_constraints) Found duplicates for column_constraints
18-05-2020 09:31:27 DEBUG tests.test_acceptance.acceptance_base_class (test_check_column_length) Certificate column lengths:
0 : 11,
1 : 6,
2 : 7,
3 : 3,
4 : 1,
5 : 8,
6 : 200,


18-05-2020 09:31:27 DEBUG tests.test_acceptance.acceptance_base_class (test_check_column_length) Subtest OK

18-05-2020 09:31:27 ERROR tests.test_acceptance.acceptance_base_class (test_check_column_length) Wrong length for pv column.Expected 2 
Traceback (most recent call last):
  File "C:\Users\buzzulini\Documents\GitHub\I2FVG_scripts\innovation_intelligence\tests\test_acceptance\acceptance_base_class.py", line 96, in test_check_column_length
    cert_check_length[i]
  File "C:\Users\buzzulini\.conda\envs\envWorking\lib\unittest\case.py", line 1257, in assertGreaterEqual
    self.fail(self._formatMessage(msg, standardMsg))
  File "C:\Users\buzzulini\.conda\envs\envWorking\lib\unittest\case.py", line 693, in fail
    raise self.failureException(msg)
AssertionError: 2 not greater than or equal to 6
18-05-2020 09:31:27 DEBUG tests.test_acceptance.acceptance_base_class (test_check_column_length) Subtest OK

18-05-2020 09:31:27 DEBUG tests.test_acceptance.acceptance_base_class (test_check_column_length) Subtest OK

18-05-2020 09:31:27 DEBUG tests.test_acceptance.acceptance_base_class (test_check_column_length) Subtest OK

18-05-2020 09:31:27 DEBUG tests.test_acceptance.acceptance_base_class (test_check_column_length) Subtest OK

18-05-2020 09:31:27 ERROR tests.test_acceptance.acceptance_base_class (test_check_column_length) Found wrong column lengths for pv columns
Traceback (most recent call last):
  File "C:\Users\buzzulini\Documents\GitHub\I2FVG_scripts\innovation_intelligence\tests\test_acceptance\acceptance_base_class.py", line 110, in test_check_column_length
    self.assertTrue(len(invalid_column_list) == 0)
  File "C:\Users\buzzulini\.conda\envs\envWorking\lib\unittest\case.py", line 705, in assertTrue
    raise self.failureException(msg)
AssertionError: False is not true
18-05-2020 09:31:27 DEBUG tests.test_acceptance.acceptance_base_class (test_check_column_nullables) Certificate column nullables:
0 : False,
1 : False,
2 : False,
3 : False,
4 : True,
5 : True,
6 : True,


18-05-2020 09:31:27 DEBUG tests.test_acceptance.acceptance_base_class (test_check_column_nullables) Test OK

18-05-2020 09:31:27 DEBUG tests.test_acceptance.acceptance_base_class (test_check_column_number) Certificate 7 column number
18-05-2020 09:31:27 DEBUG tests.test_acceptance.acceptance_base_class (test_check_column_number) Test OK

18-05-2020 09:31:28 DEBUG tests.test_acceptance.acceptance_base_class (test_check_column_types) Certificate column types: 
0 : object,
1 : object,
2 : object,
3 : int64,
4 : object,
5 : object,
6 : object,


18-05-2020 09:31:28 DEBUG tests.test_acceptance.acceptance_base_class (test_check_column_types) Test OK

18-05-2020 09:31:28 DEBUG tests.test_acceptance.acceptance_base_class (test_check_file_extension) Certificate xlsx file extension
18-05-2020 09:31:28 DEBUG tests.test_acceptance.acceptance_base_class (test_check_file_extension) Test OK

